Traceback (most recent call last):
  File "/home/luigi.cesarini/.conda/envs/my_xclim_env/lib/python3.11/site-packages/xarray/backends/file_manager.py", line 210, in _acquire_with_cache_info
    file = self._cache[self._key]
           ~~~~~~~~~~~^^^^^^^^^^^
  File "/home/luigi.cesarini/.conda/envs/my_xclim_env/lib/python3.11/site-packages/xarray/backends/lru_cache.py", line 56, in __getitem__
    value = self._cache[key]
            ~~~~~~~~~~~^^^^^
KeyError: [<class 'netCDF4._netCDF4.Dataset'>, ('/mnt/beegfs/lcesarini/DATA_FPS/ECMWF-ERAINT/KIT/CPM/mw/mw_KIT_ECMWF-ERAINT_200001010000-200012312300.nc',), 'r', (('clobber', True), ('diskless', False), ('format', 'NETCDF4'), ('persist', False)), '858510cf-650d-48b4-8fbe-1ce99e13df3b']

During handling of the above exception, another exception occurred:

Traceback (most recent call last):
  File "/mnt/beegfs/lcesarini/2022_resilience/resilience/./bias/bias_corr_wind.py", line 147, in <module>
    mod_train=xr.open_mfdataset([item for list in list_mod_train for item in list]).load()
              ^^^^^^^^^^^^^^^^^^^^^^^^^^^^^^^^^^^^^^^^^^^^^^^^^^^^^^^^^^^^^^^^^^^^^
  File "/home/luigi.cesarini/.conda/envs/my_xclim_env/lib/python3.11/site-packages/xarray/backends/api.py", line 1038, in open_mfdataset
    datasets = [open_(p, **open_kwargs) for p in paths]
               ^^^^^^^^^^^^^^^^^^^^^^^^^^^^^^^^^^^^^^^^
  File "/home/luigi.cesarini/.conda/envs/my_xclim_env/lib/python3.11/site-packages/xarray/backends/api.py", line 1038, in <listcomp>
    datasets = [open_(p, **open_kwargs) for p in paths]
                ^^^^^^^^^^^^^^^^^^^^^^^
  File "/home/luigi.cesarini/.conda/envs/my_xclim_env/lib/python3.11/site-packages/xarray/backends/api.py", line 566, in open_dataset
    backend_ds = backend.open_dataset(
                 ^^^^^^^^^^^^^^^^^^^^^
  File "/home/luigi.cesarini/.conda/envs/my_xclim_env/lib/python3.11/site-packages/xarray/backends/netCDF4_.py", line 588, in open_dataset
    store = NetCDF4DataStore.open(
            ^^^^^^^^^^^^^^^^^^^^^^
  File "/home/luigi.cesarini/.conda/envs/my_xclim_env/lib/python3.11/site-packages/xarray/backends/netCDF4_.py", line 389, in open
    return cls(manager, group=group, mode=mode, lock=lock, autoclose=autoclose)
           ^^^^^^^^^^^^^^^^^^^^^^^^^^^^^^^^^^^^^^^^^^^^^^^^^^^^^^^^^^^^^^^^^^^^
  File "/home/luigi.cesarini/.conda/envs/my_xclim_env/lib/python3.11/site-packages/xarray/backends/netCDF4_.py", line 336, in __init__
    self.format = self.ds.data_model
                  ^^^^^^^
  File "/home/luigi.cesarini/.conda/envs/my_xclim_env/lib/python3.11/site-packages/xarray/backends/netCDF4_.py", line 398, in ds
    return self._acquire()
           ^^^^^^^^^^^^^^^
  File "/home/luigi.cesarini/.conda/envs/my_xclim_env/lib/python3.11/site-packages/xarray/backends/netCDF4_.py", line 392, in _acquire
    with self._manager.acquire_context(needs_lock) as root:
  File "/home/luigi.cesarini/.conda/envs/my_xclim_env/lib/python3.11/contextlib.py", line 137, in __enter__
    return next(self.gen)
           ^^^^^^^^^^^^^^
  File "/home/luigi.cesarini/.conda/envs/my_xclim_env/lib/python3.11/site-packages/xarray/backends/file_manager.py", line 198, in acquire_context
    file, cached = self._acquire_with_cache_info(needs_lock)
                   ^^^^^^^^^^^^^^^^^^^^^^^^^^^^^^^^^^^^^^^^^
  File "/home/luigi.cesarini/.conda/envs/my_xclim_env/lib/python3.11/site-packages/xarray/backends/file_manager.py", line 216, in _acquire_with_cache_info
    file = self._opener(*self._args, **kwargs)
           ^^^^^^^^^^^^^^^^^^^^^^^^^^^^^^^^^^^
  File "src/netCDF4/_netCDF4.pyx", line 2449, in netCDF4._netCDF4.Dataset.__init__
  File "src/netCDF4/_netCDF4.pyx", line 2012, in netCDF4._netCDF4._ensure_nc_success
OSError: [Errno -101] NetCDF: HDF error: '/mnt/beegfs/lcesarini/DATA_FPS/ECMWF-ERAINT/KIT/CPM/mw/mw_KIT_ECMWF-ERAINT_200001010000-200012312300.nc'
srun: error: cn04: task 0: Exited with exit code 1
